<?xml version="1.0"?>
<robot xmlns:xacro="http://www.ros.org/wiki/xacro">

    <xacro:property name="wheel_width" value="0.0206"/>
    <xacro:property name="wheel_radius" value="0.0352"/>

    <xacro:property name="half_pi_rad" value="1.5707"/>

    <xacro:macro name="wheel_element" params="wheel_name wheel_position">
        <link name="${wheel_name}">
            <visual>
                <geometry>
                    <cylinder length="${wheel_width}" radius="${wheel_radius}"/>
                </geometry>
                <origin rpy="0 ${half_pi_rad} 0" xyz="0 0 0"/>
            </visual>

            <collision>
                <geometry>
                    <cylinder length="${wheel_width}" radius="${wheel_radius}"/>
                </geometry>
                <origin rpy="0 ${half_pi_rad} 0" xyz="0 0 0"/>
            </collision>

            <inertial>
                <origin rpy="0 ${half_pi_rad} 0" xyz="0 0 0"/>
                <mass value="0.1"/>
                <inertia ixx="0.00003451" ixy="0" ixz="0" iyy="0.00003451" iyz="0" izz="0.00006195"/>
            </inertial>
        </link>

        <joint name="${wheel_name}_chassis_link_joint" type="continuous">
            <origin rpy="0 0 0" xyz="${wheel_position}" />
            <parent link="chassis" />
            <child link="${wheel_name}" />
            <axis rpy="0 0 0" xyz="1 0 0"/>
            <limit effort="10000" velocity="1000"/>
            <joint_properties damping="1.0" friction="1.0"/>
        </joint>

        <gazebo reference="${wheel_name}">
            <kp>1000000000000000000000000000.0</kp>
            <kd>1000000000000000000000000000.0</kd>
            <mu1>10.0</mu1>
            <mu2>10.0</mu2>
        </gazebo>
    </xacro:macro>  

    <xacro:macro name="caster_element" params="caster_name caster_position">
        <link name="${caster_name}">
            <visual>
                <geometry>
                    <sphere radius="0.0252"/>
                </geometry>
            </visual>

            <visual>
                <origin rpy="0 0 0" xyz="0 0 -0.0252"/>
                <geometry>
                    <sphere radius="0.01"/>
                </geometry>
            </visual>

            <collision>
                <geometry>
                    <sphere radius="0.0352"/>
                </geometry>
            </collision>

            <inertial>
                <mass value="0.01"/>
                <origin rpy="0 ${half_pi_rad} ${half_pi_rad}" xyz="0 0 0"/>
                <inertia ixx="0.000004234" ixy="0" ixz="0" iyy="0.000004234" iyz="0" izz="0.000004234"/>
            </inertial>
        </link>

        <joint name="${caster_name}_chassis_link_joint" type="fixed">
            <origin rpy="0 0 0" xyz="${caster_position}" />
            <parent link="chassis" />
            <child link="${caster_name}" />
        </joint>

        <gazebo reference="${caster_name}">
            <kp>1000000000000000000000000000.0</kp>
            <kd>1000000000000000000000000000.0</kd>
            <mu1>0</mu1>
            <mu2>0</mu2>
        </gazebo>
    </xacro:macro> 
</robot>