<?xml version="1.0"?>
<robot name="box_bot">

  <link name="base_link">
  </link>

  <!-- Body -->
    <link name="chassis">
        <visual>
            <geometry>
                <cylinder length="0.155" radius="0.178"/>
            </geometry>
        </visual>

        <collision>
            <geometry>
                <cylinder length="0.155" radius="0.178"/>
            </geometry>
        </collision>

        <inertial>
            <mass value="0.5"/>
            <origin rpy="0 0 0" xyz="0 0 0"/>
            <inertia ixx="0.004962" ixy="0" ixz="0" iyy="0.004962" iyz="0" izz="0.007921"/>
        </inertial>
    </link>

    <joint name="base_chassis_link_joint" type="fixed">
        <origin rpy="0 0 0" xyz="0 0 0" />
        <parent link="base_link" />
        <child link="chassis" />
    </joint>

  <!-- laser -->
    <link name="laser_base">
        <visual>
            <geometry>
                <cylinder length="0.03" radius="0.02"/>
            </geometry>
            <origin rpy="0 0 0" xyz="0 0 0.015"/>
        </visual>

        <collision>
            <geometry>
                <cylinder length="0.03" radius="0.02"/>
            </geometry>
            <origin rpy="0 0 0" xyz="0 0 0.015"/>
        </collision>

        <inertial>
            <mass value="0.01"/>
            <origin rpy="0 0 0" xyz="0 0 0.015"/>
            <inertia ixx="0.00000175" ixy="0" ixz="0" iyy="0.00000175" iyz="0" izz="0.000002"/>
        </inertial>
    </link>

    <link name="laser_frame">
        <visual>
            <geometry>
                <mesh filename="package://barista_robot_description/meshes/hokuyo3d.dae" scale="0.5 0.5 0.5"/>
            </geometry>
            <origin rpy="0 0 0" xyz="0 0 0.02"/>
        </visual>

        <collision>
            <geometry>
                <cylinder length="0.04" radius="0.015"/>
            </geometry>
            <origin rpy="0 0 0" xyz="0 0 0.02"/>
        </collision>

        <inertial>
            <mass value="0.01"/>
            <inertia ixx="0.0001339" ixy="0" ixz="0" iyy="0.0001339" iyz="0" izz="0.000001125"/>
        </inertial>
    </link>

    <joint name="laser_base_chassis_link_joint" type="fixed">
        <origin rpy="0 0 0" xyz="0 0.1 0.0775" />
        <parent link="chassis" />
        <child link="laser_base" />
    </joint>

    <joint name="laser_frame_laser_base_link_joint" type="fixed">
        <origin rpy="0 0 0" xyz="0 0 0.015" />
        <parent link="laser_base" />
        <child link="laser_frame" />
    </joint>

  <!-- Standoffs -->
    <link name="standoff_1">
        <visual>
            <geometry>
                <cylinder length="0.220" radius="0.01"/>
            </geometry>
            <origin rpy="0 0 0" xyz="0 0 0.110" />
        </visual>

        <collision>
            <geometry>
                <cylinder length="0.220" radius="0.01"/>
            </geometry>
            <origin rpy="0 0 0" xyz="0 0 0.110" />
        </collision>

        <inertial>
            <origin rpy="0 0 0" xyz="0 0 0"/>
            <mass value="0.05"/>
            <inertia ixx="0.0002029" ixy="0" ixz="0" iyy="0.0002029" iyz="0" izz="0.0000025"/>
        </inertial>
    </link>

    <link name="standoff_2">
        <visual>
            <geometry>
                <cylinder length="0.220" radius="0.01"/>
            </geometry>
            <origin rpy="0 0 0" xyz="0 0 0.110" />
        </visual>

        <collision>
            <geometry>
                <cylinder length="0.220" radius="0.01"/>
            </geometry>
            <origin rpy="0 0 0" xyz="0 0 0.110" />
        </collision>

        <inertial>
            <origin rpy="0 0 0" xyz="0 0 0"/>
            <mass value="0.05"/>
            <inertia ixx="0.0002029" ixy="0" ixz="0" iyy="0.0002029" iyz="0" izz="0.0000025"/>
        </inertial>
    </link>

    <link name="standoff_3">
        <visual>
            <geometry>
                <cylinder length="0.220" radius="0.01"/>
            </geometry>
            <origin rpy="0 0 0" xyz="0 0 0.110" />
        </visual>

        <collision>
            <geometry>
                <cylinder length="0.220" radius="0.01"/>
            </geometry>
            <origin rpy="0 0 0" xyz="0 0 0.110" />
        </collision>

        <inertial>
            <origin rpy="0 0 0" xyz="0 0 0"/>
            <mass value="0.05"/>
            <inertia ixx="0.0002029" ixy="0" ixz="0" iyy="0.0002029" iyz="0" izz="0.0000025"/>
        </inertial>
    </link>

    <link name="standoff_4">
        <visual>
            <geometry>
                <cylinder length="0.220" radius="0.01"/>
            </geometry>
            <origin rpy="0 0 0" xyz="0 0 0.110" />
        </visual>

        <collision>
            <geometry>
                <cylinder length="0.220" radius="0.01"/>
            </geometry>
            <origin rpy="0 0 0" xyz="0 0 0.110" />
        </collision>

        <inertial>
            <origin rpy="0 0 0" xyz="0 0 0"/>
            <mass value="0.05"/>
            <inertia ixx="0.0002029" ixy="0" ixz="0" iyy="0.0002029" iyz="0" izz="0.0000025"/>
        </inertial>
    </link>

    <joint name="standoff_1_chassis_link_joint" type="fixed">
        <origin rpy="0 0 0" xyz="0.118 0.04 0.0775" />
        <parent link="chassis" />
        <child link="standoff_1" />
    </joint>

    <joint name="standoff_2_chassis_link_joint" type="fixed">
        <origin rpy="0 0 0" xyz="0.118 -0.04 0.0775" />
        <parent link="chassis" />
        <child link="standoff_2" />
    </joint>

    <joint name="standoff_3_chassis_link_joint" type="fixed">
        <origin rpy="0 0 0" xyz="-0.118 0.04 0.0775" />
        <parent link="chassis" />
        <child link="standoff_3" />
    </joint>

    <joint name="standoff_4_chassis_link_joint" type="fixed">
        <origin rpy="0 0 0" xyz="-0.118 -0.04 0.0775" />
        <parent link="chassis" />
        <child link="standoff_4" />
    </joint>

  <!-- cup tray -->
    <link name="cup_tray">
        <visual>
            <geometry>
                <cylinder length="0.090" radius="0.160"/>
            </geometry>
            <origin rpy="0 0 0" xyz="0 0 0.045" />
        </visual>

        <collision>
            <geometry>
                <cylinder length="0.090" radius="0.160"/>
            </geometry>
            <origin rpy="0 0 0" xyz="0 0 0.045" />
        </collision>

        <inertial>
            <mass value="0.1"/>
            <origin rpy="0 0 0" xyz="0 0 0.045" />
            <inertia ixx="0.0007075" ixy="0" ixz="0" iyy="0.0007075" iyz="0" izz="0.00128"/>
        </inertial>
    </link>

    <joint name="cup_tray_chassis_link_joint" type="fixed">
        <origin rpy="0 0 0" xyz="0 0 0.2975" />
        <parent link="chassis" />
        <child link="cup_tray" />
    </joint>

  <!-- wheels -->
    <link name="wheel_right">
        <visual>
            <geometry>
                <cylinder length="0.0206" radius="0.0352"/>
            </geometry>
            <origin rpy="0 1.5707 0" xyz="0 0 0"/>
        </visual>

        <collision>
            <geometry>
                <cylinder length="0.0206" radius="0.0352"/>
            </geometry>
            <origin rpy="0 1.5707 0" xyz="0 0 0"/>
        </collision>

        <inertial>
            <mass value="0.1"/>
            <origin rpy="0 1.5707 1.5707" xyz="0 0 0"/>
            <inertia ixx="0.00003451" ixy="0" ixz="0" iyy="0.00003451" iyz="0" izz="0.00006195"/>
        </inertial>
    </link>

    <link name="wheel_left">
        <visual>
            <geometry>
                <cylinder length="0.0206" radius="0.0352"/>
            </geometry>
            <origin rpy="0 1.5707 0" xyz="0 0 0"/>
        </visual>

        <collision>
            <geometry>
                <cylinder length="0.0206" radius="0.0352"/>
            </geometry>
            <origin rpy="0 1.5707 0" xyz="0 0 0"/>
        </collision>

        <inertial>
            <mass value="0.1"/>
            <origin rpy="0 1.5707 1.5707" xyz="0 0 0"/>
            <inertia ixx="0.00003451" ixy="0" ixz="0" iyy="0.00003451" iyz="0" izz="0.00006195"/>
        </inertial>
    </link>

    <joint name="wheel_right_chassis_link_joint" type="continuous">
        <origin rpy="0 0 0" xyz="0.133 0 -0.0775" />
        <parent link="chassis" />
        <child link="wheel_right" />
        <axis rpy="0 0 0" xyz="1 0 0"/>
        <limit effort="10000" velocity="1000"/>
        <joint_properties damping="1.0" friction="1.0"/>
    </joint>

    <joint name="wheel_left_chassis_link_joint" type="continuous">
        <origin rpy="0 0 0" xyz="-0.133 0 -0.0775" />
        <parent link="chassis" />
        <child link="wheel_left" />
        <axis rpy="0 0 0" xyz="1 0 0"/>
        <limit effort="10000" velocity="1000"/>
        <joint_properties damping="1.0" friction="1.0"/>
    </joint>

    <link name="caster_front">
        <visual>
            <geometry>
                <sphere radius="0.0252"/>
            </geometry>
        </visual>

        <visual>
            <origin rpy="0 0 0" xyz="0 0 -0.0252"/>
            <geometry>
                <sphere radius="0.01"/>
            </geometry>
        </visual>

        <collision>
            <geometry>
                <sphere radius="0.0352"/>
            </geometry>
        </collision>

        <inertial>
            <mass value="0.01"/>
            <origin rpy="0 1.5707 1.5707" xyz="0 0 0"/>
            <inertia ixx="0.000004234" ixy="0" ixz="0" iyy="0.000004234" iyz="0" izz="0.000004234"/>
        </inertial>
    </link>

    <joint name="caster_front_chassis_link_joint" type="fixed">
        <origin rpy="0 0 0" xyz="0 0.133 -0.0775" />
        <parent link="chassis" />
        <child link="caster_front" />
    </joint>

    <link name="caster_back">
        <visual>
            <geometry>
                <sphere radius="0.0252"/>
            </geometry>
        </visual>

        <visual>
            <origin rpy="0 0 0" xyz="0 0 -0.0252"/>
            <geometry>
                <sphere radius="0.01"/>
            </geometry>
        </visual>

        <collision>
            <geometry>
                <sphere radius="0.0352"/>
            </geometry>
        </collision>

        <inertial>
            <mass value="0.1"/>
            <origin rpy="0 0 0" xyz="0 0 0"/>
            <inertia ixx="0.000004234" ixy="0" ixz="0" iyy="0.000004234" iyz="0" izz="0.000004234"/>
        </inertial>
    </link>

    <joint name="caster_back_chassis_link_joint" type="fixed">
        <origin rpy="0 0 0" xyz="0 -0.133 -0.0775" />
        <parent link="chassis" />
        <child link="caster_back" />
    </joint>

    <gazebo reference="wheel_left">
        <kp>1000000000000000000000000000.0</kp>
        <kd>1000000000000000000000000000.0</kd>
        <mu1>10.0</mu1>
        <mu2>10.0</mu2>
    </gazebo>

    <gazebo reference="wheel_right">
        <kp>1000000000000000000000000000.0</kp>
        <kd>1000000000000000000000000000.0</kd>
        <mu1>10.0</mu1>
        <mu2>10.0</mu2>
    </gazebo>

    <gazebo reference="caster_front">
        <kp>1000000000000000000000000000.0</kp>
        <kd>1000000000000000000000000000.0</kd>
        <mu1>0</mu1>
        <mu2>0</mu2>
    </gazebo>

    <gazebo reference="caster_back">
        <kp>1000000000000000000000000000.0</kp>
        <kd>1000000000000000000000000000.0</kd>
        <mu1>0</mu1>
        <mu2>0</mu2>
    </gazebo>

    <gazebo reference="laser_frame">
        <sensor name="sensor_ray" type="ray">
            <pose>0 0 0 0 0 0</pose>
            <ray>
            <scan>
                <horizontal>
                <samples>200</samples>
                <resolution>1.0</resolution>
                <min_angle>-3.14</min_angle>
                <max_angle>3.14</max_angle>
                </horizontal>
            </scan>
            <range>
                <min>0.05</min>
                <max>5.0</max>
            </range>
            </ray>
            <always_on>true</always_on>
            <visualize>true</visualize>
            <update_rate>100.0</update_rate>
            <plugin name="laser" filename="libgazebo_ros_ray_sensor.so">
            <ros>
                <remapping>~/out:=scan</remapping>
            </ros>
            <output_type>sensor_msgs/LaserScan</output_type>
            </plugin>
        </sensor>
    </gazebo>

    <gazebo>
        <plugin filename="libgazebo_ros_diff_drive.so" name="differential_drive_controller">

        <!-- wheels -->
        <left_joint>wheel_left_chassis_link_joint</left_joint>
        <right_joint>wheel_right_chassis_link_joint</right_joint>

        <!-- kinematics -->
        <wheel_separation>0.266</wheel_separation>
        <wheel_diameter>0.0704</wheel_diameter>

        <!-- limits -->
        <max_wheel_torque>1.0</max_wheel_torque>
        <max_wheel_acceleration>2.0</max_wheel_acceleration>

        <!-- output -->
        <publish_odom>true</publish_odom>
        <publish_odom_tf>true</publish_odom_tf>

        <odometry_frame>odom</odometry_frame>
        <robot_base_frame>base_link</robot_base_frame>

        </plugin>
    </gazebo>

</robot>